Traceback (most recent call last):
  File "C:\Users\hyunoh\anaconda3\envs\spine\lib\site-packages\pandas\core\indexes\base.py", line 3653, in get_loc
    return self._engine.get_loc(casted_key)
  File "pandas\_libs\index.pyx", line 147, in pandas._libs.index.IndexEngine.get_loc
  File "pandas\_libs\index.pyx", line 176, in pandas._libs.index.IndexEngine.get_loc
  File "pandas\_libs\hashtable_class_helper.pxi", line 7080, in pandas._libs.hashtable.PyObjectHashTable.get_item
  File "pandas\_libs\hashtable_class_helper.pxi", line 7088, in pandas._libs.hashtable.PyObjectHashTable.get_item
KeyError: 'L5'

The above exception was the direct cause of the following exception:

Traceback (most recent call last):
  File "train.py", line 127, in <module>
    train_5_fold(dataset, batch_size=16, epochs=50, learning_rate=0.0001, optimizer_type='AdamW', scheduler_type='CosineAnnealingLR', device='cuda')
  File "train.py", line 49, in train_5_fold
    train_loss = train_one_epoch(model, train_loader, optimizer, criterion, device)
  File "train.py", line 85, in train_one_epoch
    for images, labels, _ in train_loader:
  File "C:\Users\hyunoh\anaconda3\envs\spine\lib\site-packages\torch\utils\data\dataloader.py", line 630, in __next__
    data = self._next_data()
  File "C:\Users\hyunoh\anaconda3\envs\spine\lib\site-packages\torch\utils\data\dataloader.py", line 673, in _next_data
    data = self._dataset_fetcher.fetch(index)  # may raise StopIteration
  File "C:\Users\hyunoh\anaconda3\envs\spine\lib\site-packages\torch\utils\data\_utils\fetch.py", line 52, in fetch
    data = [self.dataset[idx] for idx in possibly_batched_index]
  File "C:\Users\hyunoh\anaconda3\envs\spine\lib\site-packages\torch\utils\data\_utils\fetch.py", line 52, in <listcomp>
    data = [self.dataset[idx] for idx in possibly_batched_index]
  File "C:\Users\hyunoh\Documents\Codes\BMD_code\regression_function_classes.py", line 214, in __getitem__
    bmd = self.get_bmd(os.path.basename(img_path), ID)
  File "C:\Users\hyunoh\Documents\Codes\BMD_code\regression_function_classes.py", line 219, in get_bmd
    bmd = self.bmd_data[self.bmd_data['ID'].astype(str) == ID][vert_name].values[0]
  File "C:\Users\hyunoh\anaconda3\envs\spine\lib\site-packages\pandas\core\frame.py", line 3761, in __getitem__
    indexer = self.columns.get_loc(key)
  File "C:\Users\hyunoh\anaconda3\envs\spine\lib\site-packages\pandas\core\indexes\base.py", line 3655, in get_loc
    raise KeyError(key) from err
KeyError: 'L5'
